<?xml version="1.0"?>
<robot xmlns:xacro="http://www.ros.org/wiki/xacro">

    <!-- Macro for creating wheels with steering -->
    <xacro:macro name="create_wheel_with_steering" params="wheel_name steering_axis_xyz steering_origin_xyz steering_origin_rpy wheel_axis_xyz wheel_origin_xyz wheel_origin_rpy">
        <!-- Steering Joint -->
        <joint name="joint_steering_${wheel_name}" type="revolute">
            <parent link="link_body"/>
            <child link="link_steering_${wheel_name}"/>
            <axis xyz="${steering_axis_xyz}"/>
            <origin xyz="${steering_origin_xyz}" rpy="${steering_origin_rpy}"/>
            <limit effort="10.0" velocity="1.0" lower="-0.45" upper="0.45"/>
        </joint>

        <!-- Steering Link -->
        <link name="link_steering_${wheel_name}">
            <inertial>
                <origin xyz="0 0 0" rpy="0 0 0"/>
                <mass value="1.0"/>
                <inertia ixx="0.01" iyy="0.01" izz="0.01" ixy="0.0" ixz="0.0" iyz="0.0"/>
            </inertial>
        </link>
        
        <!-- Rotational Joint -->
        <joint name="joint_rotation_${wheel_name}" type="continuous">
            <parent link="link_steering_${wheel_name}"/>
            <child link="link_wheel_${wheel_name}"/>
            <axis xyz="${wheel_axis_xyz}"/>
            <origin xyz="${wheel_origin_xyz}" rpy="${wheel_origin_rpy}"/>
        </joint>

        <!-- Wheel Link -->
        <link name="link_wheel_${wheel_name}">
            <!-- Tire Mesh -->
            <visual>
                <geometry>
                    <mesh filename="package://robot_description/meshes/tire.stl" scale="1.0 1.0 1.0"/>
                </geometry>
                <material name="Black"/>
            </visual>

            <!-- Rims Mesh -->
            <visual>
                <geometry>
                    <mesh filename="package://robot_description/meshes/rims.stl" scale="1.0 1.0 1.0"/>
                </geometry>
                <material name="Black"/>
            </visual>

             <!-- Tire Mesh -->
            <collision>
                <geometry>
                    <mesh filename="package://robot_description/meshes/tire.stl" scale="1.0 1.0 1.0"/>
                </geometry>
            </collision>
            
            <!-- Rims Mesh -->
            <collision>
                <geometry>
                    <mesh filename="package://robot_description/meshes/rims.stl" scale="1.0 1.0 1.0"/>
                </geometry>
            </collision>

            <!-- Inertial -->
            <inertial>
                <origin xyz="0 0 0" rpy="0 0 0"/>
                <mass value="10.0"/>
                <inertia ixx="0.1" ixy="0.0" ixz="0.0" iyy="0.1" iyz="0.0" izz="0.1"/>
            </inertial>
        </link>
    </xacro:macro>
</robot>
